Workbook

Sheet Yarn Master
C1: 13-06-2025
B2: Anchor Yarn No. | C2: Opening Stock
B3: 6 | C3: 0
B4: 7 | C4: 0
B5: 8 | C5: 0
B6: 9 | C6: 0
B7: 10 | C7: 0
B8: 11 | C8: 0
B9: 13 | C9: 34
B10: 19 | C10: 0
B11: 20 | C11: 0
B12: 22 | C12: 0
B13: 24 | C13: 0
B14: 26 | C14: 0
... B39: 69 | C39: 0
B40: 70A | C40: 0
B41: 71A | C41: 0
B42: 72A | C42: 0
B43: 74 | C43: 0
B44: 76 | C44: 0
B45: 78 | C45: 0
B46: 85 | C46: 0
B47: 86 | C47: 0
B48: 87 | C48: 0
B49: 88 | C49: 0
B50: 89 | C50: 0
B51: 92 | C51: 0
B52: 94 | C52: 0
B53: 95 | C53: 0
B54: 96 | C54: 0
... B299: 9501 | C299: 25

Sheet Yarn Transaction
B2: Color No. | C2: Balance | E2: Sr. No. | F2: Color No. | G2: Date | H2: Stock In | I2: Stock Out | K2: Stock Check
B3: 6 | C3: =(VLOOKUP($B3,'Yarn Master'!$B$2:$C$299,2,)-SUMIF($F$3:$F$1000,$B3,$I$3:$I$1000)+SUMIF($F$3:$F$1000,$B3,$H$3:$H$1000)) -> 0 | E3: 1 | F3: 305 | G3: 13-06-2025 | I3: 3 | K3: Shade No. | L3: Qty
B4: 7 | C4: =(VLOOKUP($B4,'Yarn Master'!$B$2:$C$299,2,)-SUMIF($F$3:$F$1000,$B4,$I$3:$I$1000)+SUMIF($F$3:$F$1000,$B4,$H$3:$H$1000)) -> 0 | E4: 2 | F4: 280 | G4: 13-06-2025 | I4: 3 | K4: 256 | L4: =iferror(VLOOKUP($K4,$B$2:$C$299,2,FALSE),0) -> 0
B5: 8 | C5: =(VLOOKUP($B5,'Yarn Master'!$B$2:$C$299,2,)-SUMIF($F$3:$F$1000,$B5,$I$3:$I$1000)+SUMIF($F$3:$F$1000,$B5,$H$3:$H$1000)) -> 0 | E5: 3 | F5: 330 | G5: 13-06-2025 | I5: 3 | K5: 362 | L5: =iferror(VLOOKUP($K5,$B$2:$C$299,2,FALSE),0) -> 0
B6: 9 | C6: =(VLOOKUP($B6,'Yarn Master'!$B$2:$C$299,2,)-SUMIF($F$3:$F$1000,$B6,$I$3:$I$1000)+SUMIF($F$3:$F$1000,$B6,$H$3:$H$1000)) -> 25 | E6: 4 | F6: 330 | G6: 13-06-2025 | I6: 2 | K6: 368 | L6: =iferror(VLOOKUP($K6,$B$2:$C$299,2,FALSE),0) -> 0
B7: 10 | C7: =(VLOOKUP($B7,'Yarn Master'!$B$2:$C$299,2,)-SUMIF($F$3:$F$1000,$B7,$I$3:$I$1000)+SUMIF($F$3:$F$1000,$B7,$H$3:$H$1000)) -> 0 | E7: 5 | F7: 1304 | G7: 13-06-2025 | I7: 1 | K7: 9 | L7: =iferror(VLOOKUP($K7,$B$2:$C$299,2,FALSE),0) -> 25
B8: 11 | C8: =(VLOOKUP($B8,'Yarn Master'!$B$2:$C$299,2,)-SUMIF($F$3:$F$1000,$B8,$I$3:$I$1000)+SUMIF($F$3:$F$1000,$B8,$H$3:$H$1000)) -> 0 | E8: 6 | F8: 168 | G8: 13-06-2025 | I8: 1 | K8: 849 | L8: =iferror(VLOOKUP($K8,$B$2:$C$299,2,FALSE),0) -> 1
B9: 13 | C9: =(VLOOKUP($B9,'Yarn Master'!$B$2:$C$299,2,)-SUMIF($F$3:$F$1000,$B9,$I$3:$I$1000)+SUMIF($F$3:$F$1000,$B9,$H$3:$H$1000)) -> 8 | E9: 7 | F9: 204 | G9: 13-06-2025 | I9: 1 | K9: 851 | L9: =iferror(VLOOKUP($K9,$B$2:$C$299,2,FALSE),0) -> 5
B10: 19 | C10: =(VLOOKUP($B10,'Yarn Master'!$B$2:$C$299,2,)-SUMIF($F$3:$F$1000,$B10,$I$3:$I$1000)+SUMIF($F$3:$F$1000,$B10,$H$3:$H$1000)) -> 0 | E10: 8 | F10: 258 | G10: 14-06-2025 | I10: 5 | K10: 349 | L10: =iferror(VLOOKUP($K10,$B$2:$C$299,2,FALSE),0) -> 0
B11: 20 | C11: =(VLOOKUP($B11,'Yarn Master'!$B$2:$C$299,2,)-SUMIF($F$3:$F$1000,$B11,$I$3:$I$1000)+SUMIF($F$3:$F$1000,$B11,$H$3:$H$1000)) -> 0 | E11: 9 | F11: 330 | G11: 15-06-2025 | I11: 7
B12: 22 | C12: =(VLOOKUP($B12,'Yarn Master'!$B$2:$C$299,2,)-SUMIF($F$3:$F$1000,$B12,$I$3:$I$1000)+SUMIF($F$3:$F$1000,$B12,$H$3:$H$1000)) -> 0 | E12: 10 | F12: 254 | G12: 16-06-2025 | H12: 25
B13: 24 | C13: =(VLOOKUP($B13,'Yarn Master'!$B$2:$C$299,2,)-SUMIF($F$3:$F$1000,$B13,$I$3:$I$1000)+SUMIF($F$3:$F$1000,$B13,$H$3:$H$1000)) -> 32 | E13: 11 | F13: 69 | G13: 16-06-2025 | H13: 25
B14: 26 | C14: =(VLOOKUP($B14,'Yarn Master'!$B$2:$C$299,2,)-SUMIF($F$3:$F$1000,$B14,$I$3:$I$1000)+SUMIF($F$3:$F$1000,$B14,$H$3:$H$1000)) -> 47 | E14: 12 | F14: 1009 | G14: 16-06-2025 | H14: 25
B15: 27 | C15: =(VLOOKUP($B15,'Yarn Master'!$B$2:$C$299,2,)-SUMIF($F$3:$F$1000,$B15,$I$3:$I$1000)+SUMIF($F$3:$F$1000,$B15,$H$3:$H$1000)) -> 0 | E15: 13 | F15: 392 | G15: 16-06-2025 | H15: 25
B16: 28 | C16: =(VLOOKUP($B16,'Yarn Master'!$B$2:$C$299,2,)-SUMIF($F$3:$F$1000,$B16,$I$3:$I$1000)+SUMIF($F$3:$F$1000,$B16,$H$3:$H$1000)) -> 0 | E16: 14 | F16: 360 | G16: 16-06-2025 | H16: 25
B17: 29 | C17: =(VLOOKUP($B17,'Yarn Master'!$B$2:$C$299,2,)-SUMIF($F$3:$F$1000,$B17,$I$3:$I$1000)+SUMIF($F$3:$F$1000,$B17,$H$3:$H$1000)) -> 0 | E17: 15 | F17: 352 | G17: 16-06-2025 | H17: 25
B18: 31 | C18: =(VLOOKUP($B18,'Yarn Master'!$B$2:$C$299,2,)-SUMIF($F$3:$F$1000,$B18,$I$3:$I$1000)+SUMIF($F$3:$F$1000,$B18,$H$3:$H$1000)) -> 0 | E18: 16 | F18: 13 | G18: 17-06-2025 | I18: 4
B19: 33 | C19: =(VLOOKUP($B19,'Yarn Master'!$B$2:$C$299,2,)-SUMIF($F$3:$F$1000,$B19,$I$3:$I$1000)+SUMIF($F$3:$F$1000,$B19,$H$3:$H$1000)) -> 0 | E19: 17 | F19: 254 | G19: 17-06-2025 | I19: 4
B20: 35 | C20: =(VLOOKUP($B20,'Yarn Master'!$B$2:$C$299,2,)-SUMIF($F$3:$F$1000,$B20,$I$3:$I$1000)+SUMIF($F$3:$F$1000,$B20,$H$3:$H$1000)) -> 0 | E20: 18 | F20: 305 | G20: 17-06-2025 | I20: 4
B21: 46 | C21: =(VLOOKUP($B21,'Yarn Master'!$B$2:$C$299,2,)-SUMIF($F$3:$F$1000,$B21,$I$3:$I$1000)+SUMIF($F$3:$F$1000,$B21,$H$3:$H$1000)) -> 0 | E21: 19 | F21: 280 | G21: 17-06-2025 | I21: 4
B22: 47 | C22: =(VLOOKUP($B22,'Yarn Master'!$B$2:$C$299,2,)-SUMIF($F$3:$F$1000,$B22,$I$3:$I$1000)+SUMIF($F$3:$F$1000,$B22,$H$3:$H$1000)) -> 0 | E22: 20 | F22: 1304 | G22: 17-06-2025 | I22: 4
B23: 48 | C23: =(VLOOKUP($B23,'Yarn Master'!$B$2:$C$299,2,)-SUMIF($F$3:$F$1000,$B23,$I$3:$I$1000)+SUMIF($F$3:$F$1000,$B23,$H$3:$H$1000)) -> 0 | E23: 21 | F23: 254 | G23: 18-06-2025 | I23: 6
B24: 49 | C24: =(VLOOKUP($B24,'Yarn Master'!$B$2:$C$299,2,)-SUMIF($F$3:$F$1000,$B24,$I$3:$I$1000)+SUMIF($F$3:$F$1000,$B24,$H$3:$H$1000)) -> 0 | E24: 22 | F24: 1004 | G24: 18-06-2025 | I24: 2
B25: 50 | C25: =(VLOOKUP($B25,'Yarn Master'!$B$2:$C$299,2,)-SUMIF($F$3:$F$1000,$B25,$I$3:$I$1000)+SUMIF($F$3:$F$1000,$B25,$H$3:$H$1000)) -> 0 | E25: 23 | F25: 254 | G25: 19-06-2025 | I25: 6
B26: 52 | C26: =(VLOOKUP($B26,'Yarn Master'!$B$2:$C$299,2,)-SUMIF($F$3:$F$1000,$B26,$I$3:$I$1000)+SUMIF($F$3:$F$1000,$B26,$H$3:$H$1000)) -> 0 | E26: 24 | F26: 316 | G26: 19-06-2025 | I26: 4
B27: 54 | C27: =(VLOOKUP($B27,'Yarn Master'!$B$2:$C$299,2,)-SUMIF($F$3:$F$1000,$B27,$I$3:$I$1000)+SUMIF($F$3:$F$1000,$B27,$H$3:$H$1000)) -> 37 | E27: 25 | F27: 352 | G27: 20-06-2025 | I27: 11
B28: 55 | C28: =(VLOOKUP($B28,'Yarn Master'!$B$2:$C$299,2,)-SUMIF($F$3:$F$1000,$B28,$I$3:$I$1000)+SUMIF($F$3:$F$1000,$B28,$H$3:$H$1000)) -> 0 | E28: 26 | F28: 360 | G28: 20-06-2025 | I28: 5
B29: 56 | C29: =(VLOOKUP($B29,'Yarn Master'!$B$2:$C$299,2,)-SUMIF($F$3:$F$1000,$B29,$I$3:$I$1000)+SUMIF($F$3:$F$1000,$B29,$H$3:$H$1000)) -> 0 | E29: 27 | F29: 392 | G29: 20-06-2025 | I29: 5
... B39: 69 | C39: =(VLOOKUP($B39,'Yarn Master'!$B$2:$C$299,2,)-SUMIF($F$3:$F$1000,$B39,$I$3:$I$1000)+SUMIF($F$3:$F$1000,$B39,$H$3:$H$1000)) -> 38 | E39: 37 | F39: 360 | G39: 21-06-2025 | I39: 5
B40: 70A | C40: =(VLOOKUP($B40,'Yarn Master'!$B$2:$C$299,2,)-SUMIF($F$3:$F$1000,$B40,$I$3:$I$1000)+SUMIF($F$3:$F$1000,$B40,$H$3:$H$1000)) -> 0 | E40: 38 | F40: 352 | G40: 21-06-2025 | I40: 5
B41: 71A | C41: =(VLOOKUP($B41,'Yarn Master'!$B$2:$C$299,2,)-SUMIF($F$3:$F$1000,$B41,$I$3:$I$1000)+SUMIF($F$3:$F$1000,$B41,$H$3:$H$1000)) -> 0 | E41: 39 | F41: 303 | G41: 24-06-2025 | I41: 2
B42: 72A | C42: =(VLOOKUP($B42,'Yarn Master'!$B$2:$C$299,2,)-SUMIF($F$3:$F$1000,$B42,$I$3:$I$1000)+SUMIF($F$3:$F$1000,$B42,$H$3:$H$1000)) -> 0 | E42: 40 | F42: 1009 | G42: 24-06-2025 | I42: 3
B43: 74 | C43: =(VLOOKUP($B43,'Yarn Master'!$B$2:$C$299,2,)-SUMIF($F$3:$F$1000,$B43,$I$3:$I$1000)+SUMIF($F$3:$F$1000,$B43,$H$3:$H$1000)) -> 0 | E43: 41 | F43: 352 | G43: 24-06-2025 | I43: 1
B44: 76 | C44: =(VLOOKUP($B44,'Yarn Master'!$B$2:$C$299,2,)-SUMIF($F$3:$F$1000,$B44,$I$3:$I$1000)+SUMIF($F$3:$F$1000,$B44,$H$3:$H$1000)) -> 47 | E44: 42 | F44: 352 | G44: 25-06-2025 | I44: 3
B45: 78 | C45: =(VLOOKUP($B45,'Yarn Master'!$B$2:$C$299,2,)-SUMIF($F$3:$F$1000,$B45,$I$3:$I$1000)+SUMIF($F$3:$F$1000,$B45,$H$3:$H$1000)) -> 1 | E45: 43 | F45: 1009 | G45: 25-06-2025 | I45: 3
B46: 85 | C46: =(VLOOKUP($B46,'Yarn Master'!$B$2:$C$299,2,)-SUMIF($F$3:$F$1000,$B46,$I$3:$I$1000)+SUMIF($F$3:$F$1000,$B46,$H$3:$H$1000)) -> 0 | E46: 44 | F46: 254 | G46: 26-06-2025 | I46: 7
B47: 86 | C47: =(VLOOKUP($B47,'Yarn Master'!$B$2:$C$299,2,)-SUMIF($F$3:$F$1000,$B47,$I$3:$I$1000)+SUMIF($F$3:$F$1000,$B47,$H$3:$H$1000)) -> 0 | E47: 45 | F47: 308 | G47: 26-06-2025 | I47: 1
B48: 87 | C48: =(VLOOKUP($B48,'Yarn Master'!$B$2:$C$299,2,)-SUMIF($F$3:$F$1000,$B48,$I$3:$I$1000)+SUMIF($F$3:$F$1000,$B48,$H$3:$H$1000)) -> 0 | E48: 46 | F48: 361 | G48: 26-06-2025 | I48: 5
B49: 88 | C49: =(VLOOKUP($B49,'Yarn Master'!$B$2:$C$299,2,)-SUMIF($F$3:$F$1000,$B49,$I$3:$I$1000)+SUMIF($F$3:$F$1000,$B49,$H$3:$H$1000)) -> 0 | E49: 47 | F49: 308 | G49: 26-06-2025 | I49: 2
B50: 89 | C50: =(VLOOKUP($B50,'Yarn Master'!$B$2:$C$299,2,)-SUMIF($F$3:$F$1000,$B50,$I$3:$I$1000)+SUMIF($F$3:$F$1000,$B50,$H$3:$H$1000)) -> 0 | E50: 48 | F50: 305 | G50: 26-06-2025 | I50: 4
...
